<mujoco model="toy_car_navigation">
    <option gravity="0 0 -9.81" timestep="0.05"/>

    <visual>
        <headlight ambient="0.4 0.4 0.4" diffuse="0.7 0.7 0.7" specular="0.1 0.1 0.1"/>
    </visual>

    <worldbody>
        <light pos="0 0 6" dir="0 0 -1"/>
        <geom
            name="ground"
            type="plane"
            size="6 6 0.1"
            rgba="0.9 0.93 0.9 1"/>

        <geom type="box" pos="0 3.15 0.1" size="3.3 0.05 0.1" rgba="0.3 0.3 0.3 0.4" contype="0" conaffinity="0"/>
        <geom type="box" pos="0 -3.15 0.1" size="3.3 0.05 0.1" rgba="0.3 0.3 0.3 0.4" contype="0" conaffinity="0"/>
        <geom type="box" pos="3.15 0 0.1" size="0.05 3.3 0.1" rgba="0.3 0.3 0.3 0.4" contype="0" conaffinity="0"/>
        <geom type="box" pos="-3.15 0 0.1" size="0.05 3.3 0.1" rgba="0.3 0.3 0.3 0.4" contype="0" conaffinity="0"/>

        <body name="goal" mocap="true" pos="1.2 0 0.02">
            <geom
                type="cylinder"
                size="0.30 0.012"
                rgba="0.1 0.8 0.3 0.28"
                contype="0"
                conaffinity="0"/>
            <geom
                type="box"
                pos="0.18 0 0.03"
                size="0.10 0.02 0.02"
                rgba="0.1 0.7 0.2 0.95"
                contype="0"
                conaffinity="0"/>
        </body>

        <body name="car" pos="0 0 0.12">
            <joint name="car_x" type="slide" axis="1 0 0"/>
            <joint name="car_y" type="slide" axis="0 1 0"/>
            <joint name="car_yaw" type="hinge" axis="0 0 1"/>

            <geom
                name="chassis"
                type="box"
                size="0.22 0.11 0.04"
                rgba="0.13 0.35 0.87 1"/>
            <geom
                name="cabin"
                type="box"
                pos="-0.02 0 0.055"
                size="0.09 0.08 0.03"
                rgba="0.84 0.93 1 0.55"/>
            <geom
                name="front_bumper"
                type="box"
                pos="0.25 0 0"
                size="0.03 0.095 0.016"
                rgba="0.12 0.12 0.15 1"/>
            <geom
                name="rear_bumper"
                type="box"
                pos="-0.25 0 0"
                size="0.03 0.095 0.016"
                rgba="0.12 0.12 0.15 1"/>
            <site name="car_nose" pos="0.28 0 0.02" size="0.01" rgba="1 0 0 1"/>

            <body name="front_left_mount" pos="0.14 0.12 -0.02">
                <inertial pos="0 0 0" mass="0.01" diaginertia="1e-5 1e-5 1e-5"/>
                <joint name="front_left_steer" type="hinge" axis="0 0 1" limited="true" range="-0.7 0.7"/>
                <body name="front_left_wheel">
                    <joint name="front_left_spin" type="hinge" axis="0 1 0"/>
                    <geom type="cylinder" size="0.04 0.025" quat="0.7071068 0.7071068 0 0" rgba="0.08 0.08 0.08 1"/>
                </body>
            </body>

            <body name="front_right_mount" pos="0.14 -0.12 -0.02">
                <inertial pos="0 0 0" mass="0.01" diaginertia="1e-5 1e-5 1e-5"/>
                <joint name="front_right_steer" type="hinge" axis="0 0 1" limited="true" range="-0.7 0.7"/>
                <body name="front_right_wheel">
                    <joint name="front_right_spin" type="hinge" axis="0 1 0"/>
                    <geom type="cylinder" size="0.04 0.025" quat="0.7071068 0.7071068 0 0" rgba="0.08 0.08 0.08 1"/>
                </body>
            </body>

            <body name="rear_left_wheel" pos="-0.14 0.12 -0.02">
                <joint name="rear_left_spin" type="hinge" axis="0 1 0"/>
                <geom type="cylinder" size="0.04 0.025" quat="0.7071068 0.7071068 0 0" rgba="0.08 0.08 0.08 1"/>
            </body>

            <body name="rear_right_wheel" pos="-0.14 -0.12 -0.02">
                <joint name="rear_right_spin" type="hinge" axis="0 1 0"/>
                <geom type="cylinder" size="0.04 0.025" quat="0.7071068 0.7071068 0 0" rgba="0.08 0.08 0.08 1"/>
            </body>
        </body>

        <camera name="overview" pos="0 0 6.5" quat="1 0 0 0"/>
    </worldbody>
</mujoco>